Workbook

Sheet JUMDUK
D1: JUMLAH PENDUDUK KOTA BEKASI (LAKI-LAKI & PEREMPUAN) SEMESTER 1 TAHUN 2026
B4: NOKEC | C4: NO_KEL | D4: NAMA_KEC | E4: NAMA_KEL | F4: LAKI-LAKI | G4: PEREMPUAN | H4: JUMLAH | I4: RASIO JK | R4: NO | S4: KECAMATAN | T4: PENDUDUK (LK) | U4: PENDUDUK (PR) | V4: PENDUDUK (JML) | W4: KODE | X4: WILAYAH | Y4: L | Z4: P | AA4: JML
B5: 1 | C5: 1001 | E5: BEKASIJAYA | F5: 32963 | G5: 33420 | H5: 66383 | I5: =F5/G5 -> 0.98632555 | R5: 1 | S5: BEKASI TIMUR | T5: 136428 | U5: 137275 | V5: 273703 | W5: 32.75 | X5: KOTA BEKASI | Y5: 1285093 | Z5: 1287116 | AA5: 2572209
B6: 1 | C6: 1002 | E6: MARGAHAYU | F6: 33420 | G6: 33339 | H6: 66759 | I6: =F6/G6 -> 1.0024296 | R6: 1 | S6: BEKASIJAYA | T6: 32732 | U6: 32903 | V6: 65635 | W6: 32.75.01 | X6: BEKASI TIMUR | Y6: 137171 | Z6: 138360 | AA6: 275531
B7: 1 | C7: 1003 | E7: DURENJAYA | F7: 37922 | G7: 38596 | H7: 76518 | I7: =F7/G7 -> 0.98253705 | R7: 2 | S7: MARGAHAYU | T7: 33440 | U7: 33087 | V7: 66527 | W7: 32.75.01.1001 | X7: BEKASIJAYA | Y7: 32896 | Z7: 33235 | AA7: 66131
B8: 1 | C8: 1004 | E8: ARENJAYA | F8: 32965 | G8: 33686 | H8: 66651 | I8: =F8/G8 -> 0.97859645 | R8: 3 | S8: DURENJAYA | T8: 37440 | U8: 37919 | V8: 75359 | W8: 32.75.01.1002 | X8: MARGAHAYU | Y8: 33513 | Z8: 33311 | AA8: 66824
D9: BEKASI TIMUR | F9: =SUM(F5:F8) -> 137270 | G9: =SUM(G5:G8) -> 139041 | H9: =SUM(H5:H8) -> 276311 | R9: 4 | S9: ARENJAYA | T9: 32816 | U9: 33366 | V9: 66182 | W9: 32.75.01.1003 | X9: DURENJAYA | Y9: 37780 | Z9: 38272 | AA9: 76052
B10: 2 | C10: 1001 | E10: BINTARA | F10: 32830 | G10: 32686 | H10: 65516 | I10: =F10/G10 -> 1.0044056 | S10: TOTAL | T10: 136428 | U10: 137275 | V10: 273703 | W10: 32.75.01.1004 | X10: ARENJAYA | Y10: 32982 | Z10: 33542 | AA10: 66524
B11: 2 | C11: 1002 | E11: KRANJI | F11: 24910 | G11: 25009 | H11: 49919 | I11: =F11/G11 -> 0.99604143 | R11: 2 | S11: BEKASI BARAT | T11: 133054 | U11: 133233 | V11: 266287 | W11: 32.75.02 | X11: BEKASI BARAT | Y11: 135594 | Z11: 136038 | AA11: 271632
B12: 2 | C12: 1003 | E12: KOTABARU | F12: 22735 | G12: 22787 | H12: 45522 | I12: =F12/G12 -> 0.997718 | R12: 1 | S12: BINTARA | T12: 31585 | U12: 31390 | V12: 62975 | W12: 32.75.02.1001 | X12: BINTARA | Y12: 32665 | Z12: 32503 | AA12: 65168
B13: 2 | C13: 1004 | E13: BINTARAJAYA | F13: 17719 | G13: 17947 | H13: 35666 | I13: =F13/G13 -> 0.98729593 | R13: 2 | S13: KRANJI | T13: 24799 | U13: 24811 | V13: 49610 | W13: 32.75.02.1002 | X13: KRANJI | Y13: 24992 | Z13: 24997 | AA13: 49989
B14: 2 | C14: 1005 | E14: JAKASAMPURNA | F14: 37635 | G14: 37998 | H14: 75633 | I14: =F14/G14 -> 0.99044687 | R14: 3 | S14: KOTABARU | T14: 22469 | U14: 22394 | V14: 44863 | W14: 32.75.02.1003 | X14: KOTABARU | Y14: 22744 | Z14: 22805 | AA14: 45549
D15: BEKASI BARAT | F15: =SUM(F10:F14) -> 135829 | G15: =SUM(G10:G14) -> 136427 | H15: =SUM(H10:H14) -> 272256 | R15: 4 | S15: BINTARAJAYA | T15: 16991 | U15: 17168 | V15: 34159 | W15: 32.75.02.1004 | X15: BINTARAJAYA | Y15: 17617 | Z15: 17838 | AA15: 35455
B16: 3 | C16: 1001 | E16: KALIABANG TENGAH | F16: 48995 | G16: 48549 | H16: 97544 | I16: =F16/G16 -> 1.0091866 | R16: 5 | S16: JAKASAMPURNA | T16: 37210 | U16: 37470 | V16: 74680 | W16: 32.75.02.1005 | X16: JAKASAMPURNA | Y16: 37576 | Z16: 37895 | AA16: 75471
B17: 3 | C17: 1002 | E17: PERWIRA | F17: 20434 | G17: 20374 | H17: 40808 | I17: =F17/G17 -> 1.0029449 | S17: TOTAL | T17: 133054 | U17: 133233 | V17: 266287 | W17: 32.75.03 | X17: BEKASI UTARA | Y17: 172822 | Z17: 172018 | AA17: 344840
B18: 3 | C18: 1003 | E18: HARAPANBARU | F18: 14683 | G18: 14408 | H18: 29091 | I18: =F18/G18 -> 1.0190866 | R18: 3 | S18: BEKASI UTARA | T18: 169528 | U18: 168559 | V18: 338087 | W18: 32.75.03.1001 | X18: KALIABANG TENGAH | Y18: 48513 | Z18: 47989 | AA18: 96502
B19: 3 | C19: 1004 | E19: TELUK PUCUNG | F19: 36049 | G19: 35786 | H19: 71835 | I19: =F19/G19 -> 1.0073492 | R19: 1 | S19: KALIABANG TENGAH | T19: 47453 | U19: 46930 | V19: 94383 | W19: 32.75.03.1002 | X19: PERWIRA | Y19: 20165 | Z19: 19991 | AA19: 40156
B20: 3 | C20: 1005 | E20: MARGAMULYA | F20: 12596 | G20: 12447 | H20: 25043 | I20: =F20/G20 -> 1.0119708 | R20: 2 | S20: PERWIRA | T20: 19679 | U20: 19470 | V20: 39149 | W20: 32.75.03.1003 | X20: HARAPANBARU | Y20: 14251 | Z20: 13980 | AA20: 28231
B21: 3 | C21: 1006 | E21: HARAPANJAYA | F21: 41756 | G21: 42545 | H21: 84301 | I21: =F21/G21 -> 0.98145493 | R21: 3 | S21: HARAPANBARU | T21: 13731 | U21: 13504 | V21: 27235 | W21: 32.75.03.1004 | X21: TELUK PUCUNG | Y21: 35745 | Z21: 35478 | AA21: 71223
D22: BEKASI UTARA | F22: =SUM(F16:F21) -> 174513 | G22: =SUM(G16:G21) -> 174109 | H22: =SUM(H16:H21) -> 348622 | R22: 4 | S22: TELUK PUCUNG | T22: 35142 | U22: 34840 | V22: 69982 | W22: 32.75.03.1005 | X22: MARGAMULYA | Y22: 12421 | Z22: 12208 | AA22: 24629
B23: 4 | C23: 1001 | E23: PEKAYONJAYA | F23: 29952 | G23: 30980 | H23: 60932 | I23: =F23/G23 -> 0.9668173 | R23: 5 | S23: MARGAMULYA | T23: 12219 | U23: 11989 | V23: 24208 | W23: 32.75.03.1006 | X23: HARAPANJAYA | Y23: 41727 | Z23: 42372 | AA23: 84099
B24: 4 | C24: 1002 | E24: MARGAJAYA | F24: 8789 | G24: 8865 | H24: 17654 | I24: =F24/G24 -> 0.99142696 | R24: 6 | S24: HARAPANJAYA | T24: 41304 | U24: 41826 | V24: 83130 | W24: 32.75.04 | X24: BEKASI SELATAN | Y24: 107699 | Z24: 110371 | AA24: 218070
B25: 4 | C25: 1003 | E25: JAKAMULYA | F25: 18851 | G25: 19069 | H25: 37920 | I25: =F25/G25 -> 0.98856783 | S25: TOTAL | T25: 169528 | U25: 168559 | V25: 338087 | W25: 32.75.04.1001 | X25: PEKAYONJAYA | Y25: 29517 | Z25: 30572 | AA25: 60089
B26: 4 | C26: 1004 | E26: JAKASETIA | F26: 22265 | G26: 22970 | H26: 45235 | I26: =F26/G26 -> 0.96930779 | R26: 4 | S26: BEKASI SELATAN | T26: 106105 | U26: 108388 | V26: 214493 | W26: 32.75.04.1002 | X26: MARGAJAYA | Y26: 8719 | Z26: 8825 | AA26: 17544
B27: 4 | C27: 1005 | E27: KAYURINGINJAYA | F27: 29054 | G27: 29749 | H27: 58803 | I27: =F27/G27 -> 0.97663787 | R27: 1 | S27: PEKAYONJAYA | T27: 29028 | U27: 29870 | V27: 58898 | W27: 32.75.04.1003 | X27: JAKAMULYA | Y27: 18606 | Z27: 18802 | AA27: 37408
D28: BEKASI SELATAN | F28: =SUM(F23:F27) -> 108911 | G28: =SUM(G23:G27) -> 111633 | H28: =SUM(H23:H27) -> 220544 | R28: 2 | S28: MARGAJAYA | T28: 8729 | U28: 8803 | V28: 17532 | W28: 32.75.04.1004 | X28: JAKASETIA | Y28: 21909 | Z28: 22502 | AA28: 44411
B29: 5 | C29: 1001 | E29: BOJONG RAWALUMBU | F29: 40544 | G29: 40398 | H29: 80942 | I29: =F29/G29 -> 1.003614 | R29: 3 | S29: JAKAMULYA | T29: 18138 | U29: 18352 | V29: 36490 | W29: 32.75.04.1005 | X29: KAYURINGINJAYA | Y29: 28948 | Z29: 29670 | AA29: 58618
B30: 5 | C30: 1002 | E30: PENGASINAN | F30: 31507 | G30: 32114 | H30: 63621 | I30: =F30/G30 -> 0.98109859 | R30: 4 | S30: JAKASETIA | T30: 21487 | U30: 22030 | V30: 43517 | W30: 32.75.05 | X30: RAWALUMBU | Y30: 112819 | Z30: 112763 | AA30: 225582
B31: 5 | C31: 1003 | E31: SEPANJANGJAYA | F31: 18823 | G31: 18928 | H31: 37751 | I31: =F31/G31 -> 0.99445266 | R31: 5 | S31: KAYURINGINJAYA | T31: 28723 | U31: 29333 | V31: 58056 | W31: 32.75.05.1001 | X31: BOJONG RAWALUMBU | Y31: 40153 | Z31: 39778 | AA31: 79931
B32: 5 | C32: 1004 | E32: BOJONGMENTENG | F32: 22887 | G32: 22746 | H32: 45633 | I32: =F32/G32 -> 1.0061989 | S32: TOTAL | T32: 106105 | U32: 108388 | V32: 214493 | W32: 32.75.05.1002 | X32: PENGASINAN | Y32: 31335 | Z32: 31754 | AA32: 63089
D33: RAWALUMBU | F33: =SUM(F29:F32) -> 113761 | G33: =SUM(G29:G32) -> 114186 | H33: =SUM(H29:H32) -> 227947 | R33: 5 | S33: RAWALUMBU | T33: 111408 | U33: 110990 | V33: 222398 | W33: 32.75.05.1003 | X33: SEPANJANGJAYA | Y33: 18613 | Z33: 18737 | AA33: 37350
B34: 6 | C34: 1001 | E34: MEDANSATRIA | F34: 14409 | G34: 13945 | H34: 28354 | I34: =F34/G34 -> 1.0332736 | R34: 1 | S34: BOJONG RAWALUMBU | T34: 39766 | U34: 39149 | V34: 78915 | W34: 32.75.05.1004 | X34: BOJONGMENTENG | Y34: 22718 | Z34: 22494 | AA34: 45212
B35: 6 | C35: 1002 | E35: HARAPANMULYA | F35: 12844 | G35: 12534 | H35: 25378 | I35: =F35/G35 -> 1.0247327 | R35: 2 | S35: PENGASINAN | T35: 30869 | U35: 31179 | V35: 62048 | W35: 32.75.06 | X35: MEDANSATRIA | Y35: 81210 | Z35: 80156 | AA35: 161366
B36: 6 | C36: 1003 | E36: PEJUANG | F36: 38758 | G36: 39099 | H36: 77857 | I36: =F36/G36 -> 0.99127855 | R36: 3 | S36: SEPANJANGJAYA | T36: 18351 | U36: 18474 | V36: 36825 | W36: 32.75.06.1001 | X36: MEDANSATRIA | Y36: 14393 | Z36: 13913 | AA36: 28306
B37: 6 | C37: 1004 | E37: KALIBARU | F37: 15731 | G37: 15318 | H37: 31049 | I37: =F37/G37 -> 1.0269617 | R37: 4 | S37: BOJONGMENTENG | T37: 22422 | U37: 22188 | V37: 44610 | W37: 32.75.06.1002 | X37: HARAPANMULYA | Y37: 12679 | Z37: 12287 | AA37: 24966
D38: MEDAN SATRIA | F38: =SUM(F34:F37) -> 81742 | G38: =SUM(G34:G37) -> 80896 | H38: =SUM(H34:H37) -> 162638 | S38: TOTAL | T38: 111408 | U38: 110990 | V38: 222398 | W38: 32.75.06.1003 | X38: PEJUANG | Y38: 38448 | Z38: 38644 | AA38: 77092
B39: 7 | C39: 1003 | E39: BANTARGEBANG | F39: 17978 | G39: 17354 | H39: 35332 | I39: =F39/G39 -> 1.0359571 | R39: 6 | S39: MEDANSATRIA | T39: 79840 | U39: 78889 | V39: 158729 | W39: 32.75.06.1004 | X39: KALIBARU | Y39: 15690 | Z39: 15312 | AA39: 31002
B40: 7 | C40: 1004 | E40: CIKIWUL | F40: 15265 | G40: 14577 | H40: 29842 | I40: =F40/G40 -> 1.0471976 | R40: 1 | S40: MEDANSATRIA | T40: 14273 | U40: 13841 | V40: 28114 | W40: 32.75.07 | X40: BANTARGEBANG | Y40: 59754 | Z40: 57632 | AA40: 117386
B41: 7 | C41: 1007 | E41: CIKETINGUDIK | F41: 13850 | G41: 13413 | H41: 27263 | I41: =F41/G41 -> 1.0325803 | R41: 2 | S41: HARAPANMULYA | T41: 12381 | U41: 12027 | V41: 24408 | W41: 32.75.07.1003 | X41: BANTARGEBANG | Y41: 17668 | Z41: 17003 | AA41: 34671
B42: 7 | C42: 1008 | E42: SUMURBATU | F42: 14324 | G42: 14148 | H42: 28472 | I42: =F42/G42 -> 1.0124399 | R42: 3 | S42: PEJUANG | T42: 37677 | U42: 37833 | V42: 75510 | W42: 32.75.07.1004 | X42: CIKIWUL | Y42: 14953 | Z42: 14191 | AA42: 29144
...

Sheet JUMDUK KEC& KEL (GRAPH)
A1: JUMLAH PENDUDUK KOTA BEKASI (LAKI-LAKI & PEREMPUAN) SEMESTER 1 TAHUN 2026
A3: NO_KEC | B3: NO_KEL | C3: NAMA_KEC | D3: NAMA_KEL | E3: LAKI-LAKI | F3: PEREMPUAN | G3: JUMLAH | H3: RASIO JK | I3: PROSENTASE (%)
A4: 1 | B4: 1001 | C4: BEKASI TIMUR | D4: BEKASI JAYA | E4: 32963 | F4: 33420 | G4: 66383 | H4: =E4/F4 -> 0.98632555 | I4: =(G4/$G$72)*100 -> 2.5460946
A5: 1 | B5: 1002 | D5: MARGAHAYU | E5: 33420 | F5: 33339 | G5: 66759 | H5: =E5/F5 -> 1.0024296 | I5: =(G5/$G$72)*100 -> 2.5605159
A6: 1 | B6: 1003 | D6: DUREN JAYA | E6: 37922 | F6: 38596 | G6: 76518 | H6: =E6/F6 -> 0.98253705 | I6: =(G6/$G$72)*100 -> 2.9348186
A7: 1 | B7: 1004 | D7: AREN JAYA | E7: 32965 | F7: 33686 | G7: 66651 | H7: =E7/F7 -> 0.97859645 | I7: =(G7/$G$72)*100 -> 2.5563736
C8: TOTAL | E8: =SUM(E4:E7) -> 137270 | F8: =SUM(F4:F7) -> 139041 | G8: =SUM(G4:G7) -> 276311 | H8: =E8/F8 -> 0.98726275 | I8: =G8/$G$72*100 -> 10.597803
A9: 2 | B9: 1001 | C9: BEKASI BARAT | D9: BINTARA | E9: 32830 | F9: 32686 | G9: 65516 | H9: =E9/F9 -> 1.0044056 | I9: =(G9/$G$72)*100 -> 2.5128411
A10: 2 | B10: 1002 | D10: KRANJI | E10: 24910 | F10: 25009 | G10: 49919 | H10: =E10/F10 -> 0.99604143 | I10: =(G10/$G$72)*100 -> 1.9146242
A11: 2 | B11: 1003 | D11: KOTA BARU | E11: 22735 | F11: 22787 | G11: 45522 | H11: =E11/F11 -> 0.997718 | I11: =(G11/$G$72)*100 -> 1.7459789
A12: 2 | B12: 1004 | D12: BINTARA JAYA | E12: 17719 | F12: 17947 | G12: 35666 | H12: =E12/F12 -> 0.98729593 | I12: =(G12/$G$72)*100 -> 1.3679558
A13: 2 | B13: 1005 | D13: JAKA SAMPURNA | E13: 37635 | F13: 37998 | G13: 75633 | H13: =E13/F13 -> 0.99044687 | I13: =(G13/$G$72)*100 -> 2.9008748
C14: TOTAL | E14: =SUM(E9:E13) -> 135829 | F14: =SUM(F9:F13) -> 136427 | G14: =SUM(G9:G13) -> 272256 | H14: =E14/F14 -> 0.9956167 | I14: =G14/$G$72*100 -> 10.442275
A15: 3 | B15: 1001 | C15: BEKASI UTARA | D15: KALIABANG TENGAH | E15: 48995 | F15: 48549 | G15: 97544 | H15: =E15/F15 -> 1.0091866 | I15: =(G15/$G$72)*100 -> 3.7412628
A16: 3 | B16: 1002 | D16: PERWIRA | E16: 20434 | F16: 20374 | G16: 40808 | H16: =E16/F16 -> 1.0029449 | I16: =(G16/$G$72)*100 -> 1.5651752
A17: 3 | B17: 1003 | D17: HARAPAN BARU | E17: 14683 | F17: 14408 | G17: 29091 | H17: =E17/F17 -> 1.0190866 | I17: =(G17/$G$72)*100 -> 1.1157742
A18: 3 | B18: 1004 | D18: TELUK PUCUNG | E18: 36049 | F18: 35786 | G18: 71835 | H18: =E18/F18 -> 1.0073492 | I18: =(G18/$G$72)*100 -> 2.755204
A19: 3 | B19: 1005 | D19: MARGA MULYA | E19: 12596 | F19: 12447 | G19: 25043 | H19: =E19/F19 -> 1.0119708 | I19: =(G19/$G$72)*100 -> 0.96051469
A20: 3 | B20: 1006 | D20: HARAPAN JAYA | E20: 41756 | F20: 42545 | G20: 84301 | H20: =E20/F20 -> 0.98145493 | I20: =(G20/$G$72)*100 -> 3.2333326
C21: TOTAL | E21: =SUM(E15:E20) -> 174513 | F21: =SUM(F15:F20) -> 174109 | G21: =SUM(G15:G20) -> 348622 | H21: =E21/F21 -> 1.0023204 | I21: =G21/$G$72*100 -> 13.371263
A22: 4 | B22: 1001 | C22: BEKASI SELATAN | D22: PEKAYON JAYA | E22: 29952 | F22: 30980 | G22: 60932 | H22: =E22/F22 -> 0.9668173 | I22: =(G22/$G$72)*100 -> 2.3370236
A23: 4 | B23: 1002 | D23: MARGA JAYA | E23: 8789 | F23: 8865 | G23: 17654 | H23: =E23/F23 -> 0.99142696 | I23: =(G23/$G$72)*100 -> 0.67711242
A24: 4 | B24: 1003 | D24: JAKA MULYA | E24: 18851 | F24: 19069 | G24: 37920 | H24: =E24/F24 -> 0.98856783 | I24: =(G24/$G$72)*100 -> 1.4544071
A25: 4 | B25: 1004 | D25: JAKA SETIA | E25: 22265 | F25: 22970 | G25: 45235 | H25: =E25/F25 -> 0.96930779 | I25: =(G25/$G$72)*100 -> 1.7349711
A26: 4 | B26: 1005 | D26: KAYURINGIN JAYA | E26: 29054 | F26: 29749 | G26: 58803 | H26: =E26/F26 -> 0.97663787 | I26: =(G26/$G$72)*100 -> 2.2553666
C27: TOTAL | E27: =SUM(E22:E26) -> 108911 | F27: =SUM(F22:F26) -> 111633 | G27: =SUM(G22:G26) -> 220544 | H27: =E27/F27 -> 0.97561653 | I27: =G27/$G$72*100 -> 8.4588808
A28: 5 | B28: 1001 | C28: RAWALUMBU | D28: BOJONG RAWALUMBU | E28: 40544 | F28: 40398 | G28: 80942 | H28: =E28/F28 -> 1.003614 | I28: =(G28/$G$72)*100 -> 3.1044995
A29: 5 | B29: 1002 | D29: PENGASINAN | E29: 31507 | F29: 32114 | G29: 63621 | H29: =E29/F29 -> 0.98109859 | I29: =(G29/$G$72)*100 -> 2.4401591
A30: 5 | B30: 1003 | D30: SEPANJANG JAYA | E30: 18823 | F30: 18928 | G30: 37751 | H30: =E30/F30 -> 0.99445266 | I30: =(G30/$G$72)*100 -> 1.4479252
A31: 5 | B31: 1004 | D31: BOJONG MENTENG | E31: 22887 | F31: 22746 | G31: 45633 | H31: =E31/F31 -> 1.0061989 | I31: =(G31/$G$72)*100 -> 1.7502363
C32: TOTAL | E32: =SUM(E28:E31) -> 113761 | F32: =SUM(F28:F31) -> 114186 | G32: =SUM(G28:G31) -> 227947 | H32: =E32/F32 -> 0.996278 | I32: =G32/$G$72*100 -> 8.74282
A33: 6 | B33: 1001 | C33: MEDAN SATRIA | D33: MEDAN SATRIA | E33: 14409 | F33: 13945 | G33: 28354 | H33: =E33/F33 -> 1.0332736 | I33: =(G33/$G$72)*100 -> 1.0875068
A34: 6 | B34: 1002 | D34: HARAPAN MULYA | E34: 12844 | F34: 12534 | G34: 25378 | H34: =E34/F34 -> 1.0247327 | I34: =(G34/$G$72)*100 -> 0.97336349
A35: 6 | B35: 1003 | D35: PEJUANG | E35: 38758 | F35: 39099 | G35: 77857 | H35: =E35/F35 -> 0.99127855 | I35: =(G35/$G$72)*100 -> 2.9861755
A36: 6 | B36: 1004 | D36: KALI BARU | E36: 15731 | F36: 15318 | G36: 31049 | H36: =E36/F36 -> 1.0269617 | I36: =(G36/$G$72)*100 -> 1.1908725
C37: TOTAL | E37: =SUM(E33:E36) -> 81742 | F37: =SUM(F33:F36) -> 80896 | G37: =SUM(G33:G36) -> 162638 | H37: =E37/F37 -> 1.0104579 | I37: =G37/G72*100 -> 6.2379183
A38: 7 | B38: 1003 | C38: BANTARGEBANG | D38: BANTAR GEBANG | E38: 17978 | F38: 17354 | G38: 35332 | H38: =E38/F38 -> 1.0359571 | I38: =(G38/$G$72)*100 -> 1.3551453
A39: 7 | B39: 1004 | D39: CIKIWUL | E39: 15265 | F39: 14577 | G39: 29842 | H39: =E39/F39 -> 1.0471976 | I39: =(G39/$G$72)*100 -> 1.1445785
A40: 7 | B40: 1007 | D40: CIKETINGUDIK | E40: 13850 | F40: 13413 | G40: 27263 | H40: =E40/F40 -> 1.0325803 | I40: =(G40/$G$72)*100 -> 1.0456619
A41: 7 | B41: 1008 | D41: SUMUR BATU | E41: 14324 | F41: 14148 | G41: 28472 | H41: =E41/F41 -> 1.0124399 | I41: =(G41/$G$72)*100 -> 1.0920327
...

Sheet JUM_KK
A1: JUMLAH KELUARGA KOTA BEKASI (BERDASARKAN KK)
A2: SEMESTER 1 TAHUN 2026
A4: NO_KEC | B4: NO_KEL | C4: NAMA_KEC | D4: NAMA_KEL | E4: LAKI LAKI | F4: PEREMPUAN | G4: JUMLAH | H4: JUMLAH VERSI BNBA | J4: NO_KEC | K4: NO_KEL | L4: NAMA_KEC | M4: NAMA_KEL | N4: JUMLAH | Q4: KODE | R4: WILAYAH | S4: LK | T4: PR | U4: JML
A5: 1 | B5: 1001 | C5: BEKASI TIMUR | D5: BEKASIJAYA | E5: 16538 | F5: 4883 | G5: 21421 | H5: 20274 | J5: 1 | K5: 1001 | L5: BEKASI TIMUR | M5: BEKASI JAYA | N5: 20274 | Q5: 32.75 | R5: KOTA BEKASI | S5: 653115 | T5: 165483 | U5: 818598
A6: 1 | B6: 1002 | C6: BEKASI TIMUR | D6: MARGAHAYU | E6: 17006 | F6: 4987 | G6: 21993 | H6: 21587 | J6: 1 | K6: 1002 | L6: BEKASI TIMUR | M6: MARGAHAYU | N6: 21587 | Q6: 32.75.01 | R6: BEKASI TIMUR | S6: 69598 | T6: 19463 | U6: 89061
A7: 1 | B7: 1003 | C7: BEKASI TIMUR | D7: DURENJAYA | E7: 19312 | F7: 5325 | G7: 24637 | H7: 23458 | J7: 1 | K7: 1003 | L7: BEKASI TIMUR | M7: DUREN JAYA | N7: 23458 | Q7: 32.75.01.1001 | R7: BEKASIJAYA | S7: 16511 | T7: 4651 | U7: 21162
A8: 1 | B8: 1004 | C8: BEKASI TIMUR | D8: ARENJAYA | E8: 16740 | F8: 4991 | G8: 21731 | H8: 20819 | J8: 1 | K8: 1004 | L8: BEKASI TIMUR | M8: AREN JAYA | N8: 20819 | Q8: 32.75.01.1002 | R8: MARGAHAYU | S8: 17042 | T8: 4878 | U8: 21920
E9: =SUM(E3:E8) -> 69596 | F9: =SUM(F3:F8) -> 20186 | G9: =SUM(G3:G8) -> 89782 | H9: =SUM(H5:H8) -> 86138 | I9: 86138 | J9: 2 | K9: 1001 | L9: BEKASI BARAT | M9: BINTARA | N9: 20083 | Q9: 32.75.01.1003 | R9: DURENJAYA | S9: 19305 | T9: 5151 | U9: 24456
A10: 2 | B10: 1001 | C10: BEKASI BARAT | D10: BINTARA | E10: 16498 | F10: 4710 | G10: 21208 | H10: 20083 | J10: 2 | K10: 1002 | L10: BEKASI BARAT | M10: KRANJI | N10: 15986 | Q10: 32.75.01.1004 | R10: ARENJAYA | S10: 16740 | T10: 4783 | U10: 21523
A11: 2 | B11: 1002 | C11: BEKASI BARAT | D11: KRANJI | E11: 12620 | F11: 3595 | G11: 16215 | H11: 15986 | J11: 2 | K11: 1003 | L11: BEKASI BARAT | M11: KOTA BARU | N11: 14363 | Q11: 32.75.02 | R11: BEKASI BARAT | S11: 68976 | T11: 19193 | U11: 88169
A12: 2 | B12: 1003 | C12: BEKASI BARAT | D12: KOTABARU | E12: 11730 | F12: 3196 | G12: 14926 | H12: 14363 | J12: 2 | K12: 1004 | L12: BEKASI BARAT | M12: BINTARA JAYA | N12: 10789 | Q12: 32.75.02.1001 | R12: BINTARA | S12: 16506 | T12: 4530 | U12: 21036
A13: 2 | B13: 1004 | C13: BEKASI BARAT | D13: BINTARAJAYA | E13: 8982 | F13: 2654 | G13: 11636 | H13: 10789 | J13: 2 | K13: 1005 | L13: BEKASI BARAT | M13: JAKA SAMPURNA | N13: 24003 | Q13: 32.75.02.1002 | R13: KRANJI | S13: 12700 | T13: 3483 | U13: 16183
A14: 2 | B14: 1005 | C14: BEKASI BARAT | D14: JAKASAMPURNA | E14: 19068 | F14: 5639 | G14: 24707 | H14: 24003 | J14: 3 | K14: 1001 | L14: BEKASI UTARA | M14: KALIABANG TENGAH | N14: 27918 | Q14: 32.75.02.1003 | R14: KOTABARU | S14: 11762 | T14: 3105 | U14: 14867
E15: =SUM(E10:E14) -> 68898 | F15: =SUM(F10:F14) -> 19794 | G15: =SUM(G10:G14) -> 88692 | H15: =SUM(H10:H14) -> 85224 | I15: 85224 | J15: 3 | K15: 1002 | L15: BEKASI UTARA | M15: PERWIRA | N15: 11202 | Q15: 32.75.02.1004 | R15: BINTARAJAYA | S15: 8952 | T15: 2557 | U15: 11509
A16: 3 | B16: 1001 | C16: BEKASI UTARA | D16: KALIABANG TENGAH | E16: 24705 | F16: 5804 | G16: 30509 | H16: 27918 | J16: 3 | K16: 1003 | L16: BEKASI UTARA | M16: HARAPAN BARU | N16: 7603 | Q16: 32.75.02.1005 | R16: JAKASAMPURNA | S16: 19056 | T16: 5518 | U16: 24574
A17: 3 | B17: 1002 | C17: BEKASI UTARA | D17: PERWIRA | E17: 10207 | F17: 2259 | G17: 12466 | H17: 11202 | J17: 3 | K17: 1004 | L17: BEKASI UTARA | M17: TELUK PUCUNG | N17: 20992 | Q17: 32.75.03 | R17: BEKASI UTARA | S17: 86727 | T17: 20412 | U17: 107139
A18: 3 | B18: 1003 | C18: BEKASI UTARA | D18: HARAPANBARU | E18: 7301 | F18: 1467 | G18: 8768 | H18: 7603 | J18: 3 | K18: 1005 | L18: BEKASI UTARA | M18: MARGA MULYA | N18: 7329 | Q18: 32.75.03.1001 | R18: KALIABANG TENGAH | S18: 24432 | T18: 5505 | U18: 29937
A19: 3 | B19: 1004 | C19: BEKASI UTARA | D19: TELUK PUCUNG | E19: 18057 | F19: 4630 | G19: 22687 | H19: 20992 | J19: 3 | K19: 1006 | L19: BEKASI UTARA | M19: HARAPAN JAYA | N19: 24943 | Q19: 32.75.03.1002 | R19: PERWIRA | S19: 10099 | T19: 2121 | U19: 12220
A20: 3 | B20: 1005 | C20: BEKASI UTARA | D20: MARGAMULYA | E20: 6376 | F20: 1673 | G20: 8049 | H20: 7329 | J20: 4 | K20: 1001 | L20: BEKASI SELATAN | M20: PEKAYON JAYA | N20: 17888 | Q20: 32.75.03.1003 | R20: HARAPANBARU | S20: 7039 | T20: 1395 | U20: 8434
A21: 3 | B21: 1006 | C21: BEKASI UTARA | D21: HARAPANJAYA | E21: 21057 | F21: 5502 | G21: 26559 | H21: 24943 | J21: 4 | K21: 1002 | L21: BEKASI SELATAN | M21: MARGA JAYA | N21: 5731 | Q21: 32.75.03.1004 | R21: TELUK PUCUNG | S21: 17899 | T21: 4461 | U21: 22360
E22: =SUM(E16:E21) -> 87703 | F22: =SUM(F16:F21) -> 21335 | G22: =SUM(G16:G21) -> 109038 | H22: =SUM(H16:H21) -> 99987 | I22: 99987 | J22: 4 | K22: 1003 | L22: BEKASI SELATAN | M22: JAKA MULYA | N22: 10861 | Q22: 32.75.03.1005 | R22: MARGAMULYA | S22: 6255 | T22: 1627 | U22: 7882
A23: 4 | B23: 1001 | C23: BEKASI SELATAN | D23: PEKAYONJAYA | E23: 15334 | F23: 4238 | G23: 19572 | H23: 17888 | J23: 4 | K23: 1004 | L23: BEKASI SELATAN | M23: JAKA SETIA | N23: 13180 | Q23: 32.75.03.1006 | R23: HARAPANJAYA | S23: 21003 | T23: 5303 | U23: 26306
A24: 4 | B24: 1002 | C24: BEKASI SELATAN | D24: MARGAJAYA | E24: 4462 | F24: 1363 | G24: 5825 | H24: 5731 | J24: 4 | K24: 1005 | L24: BEKASI SELATAN | M24: KAYURINGIN JAYA | N24: 18559 | Q24: 32.75.04 | R24: BEKASI SELATAN | S24: 54740 | T24: 15272 | U24: 70012
A25: 4 | B25: 1003 | C25: BEKASI SELATAN | D25: JAKAMULYA | E25: 9572 | F25: 2461 | G25: 12033 | H25: 10861 | J25: 5 | K25: 1001 | L25: RAWALUMBU | M25: BOJONG RAWALUMBU | N25: 25139 | Q25: 32.75.04.1001 | R25: PEKAYONJAYA | S25: 15066 | T25: 4096 | U25: 19162
A26: 4 | B26: 1004 | C26: BEKASI SELATAN | D26: JAKASETIA | E26: 11454 | F26: 3056 | G26: 14510 | H26: 13180 | J26: 5 | K26: 1002 | L26: RAWALUMBU | M26: PENGASINAN | N26: 19004 | Q26: 32.75.04.1002 | R26: MARGAJAYA | S26: 4433 | T26: 1327 | U26: 5760
A27: 4 | B27: 1005 | C27: BEKASI SELATAN | D27: KAYURINGINJAYA | E27: 14618 | F27: 4674 | G27: 19292 | H27: 18559 | J27: 5 | K27: 1003 | L27: RAWALUMBU | M27: SEPANJANG JAYA | N27: 11818 | Q27: 32.75.04.1003 | R27: JAKAMULYA | S27: 9414 | T27: 2374 | U27: 11788
E28: =SUM(E23:E27) -> 55440 | F28: =SUM(F23:F27) -> 15792 | G28: =SUM(G23:G27) -> 71232 | H28: =SUM(H23:H27) -> 66219 | I28: 66219 | J28: 5 | K28: 1004 | L28: RAWALUMBU | M28: BOJONG MENTENG | N28: 14753 | Q28: 32.75.04.1004 | R28: JAKASETIA | S28: 11278 | T28: 2897 | U28: 14175
A29: 5 | B29: 1001 | C29: RAWALUMBU | D29: BOJONG RAWALUMBU | E29: 21132 | F29: 5179 | G29: 26311 | H29: 25139 | J29: 6 | K29: 1001 | L29: MEDAN SATRIA | M29: MEDAN SATRIA | N29: 8949 | Q29: 32.75.04.1005 | R29: KAYURINGINJAYA | S29: 14549 | T29: 4578 | U29: 19127
A30: 5 | B30: 1002 | C30: RAWALUMBU | D30: PENGASINAN | E30: 16084 | F30: 4220 | G30: 20304 | H30: 19004 | J30: 6 | K30: 1002 | L30: MEDAN SATRIA | M30: HARAPAN MULYA | N30: 7401 | Q30: 32.75.05 | R30: RAWALUMBU | S30: 58431 | T30: 14622 | U30: 73053
A31: 5 | B31: 1003 | C31: RAWALUMBU | D31: SEPANJANGJAYA | E31: 9758 | F31: 2645 | G31: 12403 | H31: 11818 | J31: 6 | K31: 1003 | L31: MEDAN SATRIA | M31: PEJUANG | N31: 22615 | Q31: 32.75.05.1001 | R31: BOJONG RAWALUMBU | S31: 20916 | T31: 5051 | U31: 25967
A32: 5 | B32: 1004 | C32: RAWALUMBU | D32: BOJONGMENTENG | E32: 12044 | F32: 2902 | G32: 14946 | H32: 14753 | J32: 6 | K32: 1004 | L32: MEDAN SATRIA | M32: KALI BARU | N32: 9864 | Q32: 32.75.05.1002 | R32: PENGASINAN | S32: 15931 | T32: 4115 | U32: 20046
E33: =SUM(E29:E32) -> 59018 | F33: =SUM(F29:F32) -> 14946 | G33: =SUM(G29:G32) -> 73964 | H33: =SUM(H29:H32) -> 70714 | I33: 70714 | J33: 7 | K33: 1003 | L33: BANTARGEBANG | M33: BANTARGEBANG | N33: 10619 | Q33: 32.75.05.1003 | R33: SEPANJANGJAYA | S33: 9634 | T33: 2583 | U33: 12217
A34: 6 | B34: 1001 | C34: MEDAN SATRIA | D34: MEDANSATRIA | E34: 7303 | F34: 1822 | G34: 9125 | H34: 8949 | J34: 7 | K34: 1004 | L34: BANTARGEBANG | M34: CIKIWUL | N34: 9610 | Q34: 32.75.05.1004 | R34: BOJONGMENTENG | S34: 11950 | T34: 2873 | U34: 14823
A35: 6 | B35: 1002 | C35: MEDAN SATRIA | D35: HARAPANMULYA | E35: 6360 | F35: 1689 | G35: 8049 | H35: 7401 | J35: 7 | K35: 1007 | L35: BANTARGEBANG | M35: CIKETINGUDIK | N35: 7732 | Q35: 32.75.06 | R35: MEDANSATRIA | S35: 40774 | T35: 10430 | U35: 51204
A36: 6 | B36: 1003 | C36: MEDAN SATRIA | D36: PEJUANG | E36: 19510 | F36: 5129 | G36: 24639 | H36: 22615 | J36: 7 | K36: 1008 | L36: BANTARGEBANG | M36: SUMUR BATU | N36: 7126 | Q36: 32.75.06.1001 | R36: MEDANSATRIA | S36: 7307 | T36: 1753 | U36: 9060
A37: 6 | B37: 1004 | C37: MEDAN SATRIA | D37: KALIBARU | E37: 7928 | F37: 2156 | G37: 10084 | H37: 9864 | J37: 8 | K37: 1001 | L37: PONDOKGEDE | M37: JATIWARINGIN | N37: 15251 | Q37: 32.75.06.1002 | R37: HARAPANMULYA | S37: 6263 | T37: 1635 | U37: 7898
E38: =SUM(E34:E37) -> 41101 | F38: =SUM(F34:F37) -> 10796 | G38: =SUM(G34:G37) -> 51897 | H38: =SUM(H34:H37) -> 48829 | I38: 48829 | J38: 8 | K38: 1002 | L38: PONDOKGEDE | M38: JATIBENING | N38: 12205 | Q38: 32.75.06.1003 | R38: PEJUANG | S38: 19246 | T38: 4961 | U38: 24207
A39: 7 | B39: 1003 | C39: BANTARGEBANG | D39: BANTARGEBANG | E39: 9259 | F39: 1922 | G39: 11181 | H39: 10619 | J39: 8 | K39: 1003 | L39: PONDOKGEDE | M39: JATIMAKMUR | N39: 18786 | Q39: 32.75.06.1004 | R39: KALIBARU | S39: 7958 | T39: 2081 | U39: 10039
A40: 7 | B40: 1004 | C40: BANTARGEBANG | D40: CIKIWUL | E40: 8471 | F40: 1643 | G40: 10114 | H40: 9610 | J40: 8 | K40: 1006 | L40: PONDOKGEDE | M40: JATIBENING BARU | N40: 12142 | Q40: 32.75.07 | R40: BANTARGEBANG | S40: 32135 | T40: 6401 | U40: 38536
A41: 7 | B41: 1007 | C41: BANTARGEBANG | D41: CIKETINGUDIK | E41: 7719 | F41: 1676 | G41: 9395 | H41: 7732 | J41: 8 | K41: 1007 | L41: PONDOKGEDE | M41: JATICEMPAKA | N41: 14468 | Q41: 32.75.07.1003 | R41: BANTARGEBANG | S41: 9176 | T41: 1832 | U41: 11008
...

Sheet JUM_KK KECAMATAN
A1: JUMLAH KELUARGA KOTA BEKASI (BERDASARKAN KK)
A2: DKB SEMESTER 1 TAHUN 2026
A4: NO_KEC | B4: NO_KEL | C4: NAMA_KEC | D4: NAMA_KECAMATAN | E4: JUMLAH | F4: PROSENTASE (%)
C5: AKUMULASI BEKASI TIMUR | D5: BEKASI TIMUR | E5: =JUM_KK!G9 -> 89782 | F5: =E5/$E$17*100 -> 10.789109
C6: AKUMULASI BEKASI BARAT | D6: BEKASI BARAT | E6: =JUM_KK!G15 -> 88692 | F6: =E6/$E$17*100 -> 10.658123
C7: AKUMULASI BEKASI UTARA | D7: BEKASI UTARA | E7: =JUM_KK!G22 -> 109038 | F7: =E7/$E$17*100 -> 13.103104
C8: AKUMULASI BEKASI SELATAN | D8: BEKASI SELATAN | E8: =JUM_KK!G28 -> 71232 | F8: =E8/$E$17*100 -> 8.559954
C9: AKUMULASI RAWALUMBU | D9: RAWA LUMBU | E9: =JUM_KK!G33 -> 73964 | F9: =E9/$E$17*100 -> 8.8882587
C10: AKUMULASI MEDANSATRIA | D10: MEDAN SATRIA | E10: =JUM_KK!G38 -> 51897 | F10: =E10/$E$17*100 -> 6.2364658
C11: AKUMULASI BANTARGEBANG | D11: BANTARGEBANG | E11: =JUM_KK!G43 -> 39457 | F11: =E11/$E$17*100 -> 4.7415502
C12: AKUMULASI PONDOKGEDE | D12: PONDOH GEDE | E12: =JUM_KK!G49 -> 76796 | F12: =E12/$E$17*100 -> 9.2285803
C13: AKUMULASI JATIASIH | D13: JATIASIH | E13: =JUM_KK!G56 -> 78562 | F13: =E13/$E$17*100 -> 9.4408006
C14: AKUMULASI JATISAMPURNA | D14: JATISAMPURNA | E14: =JUM_KK!G62 -> 39348 | F14: =E14/$E$17*100 -> 4.7284517
C15: AKUMULASI MUSTIKAJAYA | D15: MUJSTIKAJAYA | E15: =JUM_KK!G67 -> 69657 | F15: =E15/$E$17*100 -> 8.3706862
C16: AKUMULASI PONDOKMELATI | D16: PONDOKMELATI | E16: =JUM_KK!G72 -> 43729 | F16: =E16/$E$17*100 -> 5.2549168
A17: JUMLAH | E17: =SUM(E5,E6,E7,E8,E9,E10,E11,E12,E13,E14,E15,E16) -> 832154 | F17: =SUM(F5,F6,F7,F8,F9,F10,F11,F12,F13,F14,F15,F16) -> 100

Sheet JUMDUK_AGM
A1: JUMLAH PENDUDUK BERDASARKAN AGAMA SESUAI DKB SEMESTER 1 TAHUN 2026
A4: KODE | B4: WILAYAH | C4: ISLAM L | D4: ISLAM P | E4: JUMLAH ISLAM | F4: KRISTEN L | G4: KRISTEN P | H4: JUMLAH KRISTEN | I4: KATHOLIK L | J4: KATHOLIK P | K4: JUMLAH KATHOLIK | L4: HINDU L | M4: HINDU P | N4: JUMLAH HINDU | O4: BUDHA L | P4: BUDHA P | Q4: JUMLAH BUDHA | R4: KHONGHUCU L | S4: KHONGHUCU P | T4: JUMLAH KONGHUCU | U4: KEPERCAYAAN L | V4: KEPERCAYAAN P | W4: JUMLAH KEPERCAYAAN | X4: TOTAL L | Y4: TOTAL P | Z4: GRAND TOTAL
A5: 3275 | B5: PROSENTASE | C5: =E6/$Z$6*100 -> 88.57531 | F5: =H6/$Z$6*100 -> 7.440489 | I5: =K6/$Z$6*100 -> 2.5213175 | L5: =N6/$Z$6*100 -> 0.15940179 | O5: =Q6/$Z$6*100 -> 0.84399336 | R5: =T6/$Z$6*100 -> 0.0051011641 | U5: =W6/$Z$6*100 -> 0.020174529 | X5: =Z6/$Z$6*100 -> 100
A6: 3275 | B6: KOTA BEKASI | C6: 1160578 | D6: 1160044 | E6: 2309378 | F6: 94817 | G6: 99366 | H6: 193992 | I6: 31982 | J6: 33781 | K6: 65737 | L6: 2155 | M6: 2000 | N6: 4156 | O6: 10945 | P6: 10923 | Q6: 22005 | R6: 75 | S6: 63 | T6: 133 | U6: 270 | V6: 249 | W6: 526 | X6: =SUM(C6,F6,I6,L6,O6,R6,U6) -> 1300822 | Y6: =SUM(D6,G6,J6,M6,P6,S6,V6) -> 1306426 | Z6: =SUM(X6:Y6) -> 2607248
A7: 327501 | B7: BEKASI TIMUR | C7: 120491 | D7: 121279 | E7: 241269 | F7: 10314 | G7: 10950 | H7: 21282 | I7: 3202 | J7: 3484 | K7: 6720 | L7: 155 | M7: 176 | N7: 335 | O7: 3096 | P7: 3143 | Q7: 6279 | R7: 9 | S7: 6 | T7: 15 | U7: 3 | V7: 3 | W7: 6 | X7: =SUM(C7,F7,I7,L7,O7,R7,U7) -> 137270 | Y7: =SUM(D7,G7,J7,M7,P7,S7,V7) -> 139041 | Z7: =SUM(X7:Y7) -> 276311
A8: 3275011001 | B8: BEKASIJAYA | C8: 28421 | D8: 28384 | E8: 56666 | F8: 2245 | G8: 2533 | H8: 4774 | I8: 795 | J8: 931 | K8: 1749 | L8: 44 | M8: 45 | N8: 92 | O8: 1455 | P8: 1523 | Q8: 3013 | R8: 3 | S8: 4 | T8: 7 | U8: 0 | V8: 0 | W8: 0 | X8: =SUM(C8,F8,I8,L8,O8,R8,U8) -> 32963 | Y8: =SUM(D8,G8,J8,M8,P8,S8,V8) -> 33420 | Z8: =SUM(X8:Y8) -> 66383
A9: 3275011002 | B9: MARGAHAYU | C9: 29662 | D9: 29504 | E9: 59086 | F9: 2158 | G9: 2229 | H9: 4416 | I9: 727 | J9: 746 | K9: 1465 | L9: 38 | M9: 36 | N9: 75 | O9: 831 | P9: 823 | Q9: 1667 | R9: 1 | S9: 0 | T9: 1 | U9: 3 | V9: 1 | W9: 4 | X9: =SUM(C9,F9,I9,L9,O9,R9,U9) -> 33420 | Y9: =SUM(D9,G9,J9,M9,P9,S9,V9) -> 33339 | Z9: =SUM(X9:Y9) -> 66759
A10: 3275011003 | B10: DURENJAYA | C10: 33425 | D10: 33862 | E10: 67044 | F10: 2872 | G10: 3005 | H10: 5853 | I10: 996 | J10: 1091 | K10: 2101 | L10: 40 | M10: 51 | N10: 92 | O10: 588 | P10: 587 | Q10: 1167 | R10: 1 | S10: 0 | T10: 1 | U10: 0 | V10: 0 | W10: 0 | X10: =SUM(C10,F10,I10,L10,O10,R10,U10) -> 37922 | Y10: =SUM(D10,G10,J10,M10,P10,S10,V10) -> 38596 | Z10: =SUM(X10:Y10) -> 76518
A11: 3275011004 | B11: ARENJAYA | C11: 28983 | D11: 29529 | E11: 58473 | F11: 3039 | G11: 3183 | H11: 6239 | I11: 684 | J11: 716 | K11: 1405 | L11: 33 | M11: 44 | N11: 76 | O11: 222 | P11: 210 | Q11: 432 | R11: 4 | S11: 2 | T11: 6 | U11: 0 | V11: 2 | W11: 2 | X11: =SUM(C11,F11,I11,L11,O11,R11,U11) -> 32965 | Y11: =SUM(D11,G11,J11,M11,P11,S11,V11) -> 33686 | Z11: =SUM(X11:Y11) -> 66651
A12: 327502 | B12: BEKASI BARAT | C12: 123669 | D12: 123483 | E12: 246885 | F12: 8462 | G12: 8961 | H12: 17440 | I12: 2858 | J12: 3099 | K12: 5974 | L12: 198 | M12: 174 | N12: 371 | O12: 633 | P12: 700 | Q12: 1337 | R12: 4 | S12: 4 | T12: 8 | U12: 5 | V12: 6 | W12: 10 | X12: =SUM(C12,F12,I12,L12,O12,R12,U12) -> 135829 | Y12: =SUM(D12,G12,J12,M12,P12,S12,V12) -> 136427 | Z12: =SUM(X12:Y12) -> 272256
A13: 3275021001 | B13: BINTARA | C13: 30267 | D13: 29895 | E13: 60065 | F13: 1614 | G13: 1795 | H13: 3418 | I13: 728 | J13: 775 | K13: 1520 | L13: 39 | M13: 42 | N13: 85 | O13: 177 | P13: 175 | Q13: 358 | R13: 3 | S13: 1 | T13: 4 | U13: 2 | V13: 3 | W13: 4 | X13: =SUM(C13,F13,I13,L13,O13,R13,U13) -> 32830 | Y13: =SUM(D13,G13,J13,M13,P13,S13,V13) -> 32686 | Z13: =SUM(X13:Y13) -> 65516
A14: 3275021002 | B14: KRANJI | C14: 23335 | D14: 23317 | E14: 46728 | F14: 1138 | G14: 1243 | H14: 2397 | I14: 332 | J14: 325 | K14: 654 | L14: 19 | M14: 19 | N14: 38 | O14: 84 | P14: 104 | Q14: 191 | R14: 0 | S14: 0 | T14: 0 | U14: 2 | V14: 1 | W14: 3 | X14: =SUM(C14,F14,I14,L14,O14,R14,U14) -> 24910 | Y14: =SUM(D14,G14,J14,M14,P14,S14,V14) -> 25009 | Z14: =SUM(X14:Y14) -> 49919
A15: 3275021003 | B15: KOTABARU | C15: 20394 | D15: 20310 | E15: 40640 | F15: 1516 | G15: 1623 | H15: 3141 | I15: 630 | J15: 634 | K15: 1246 | L15: 33 | M15: 26 | N15: 59 | O15: 160 | P15: 194 | Q15: 352 | R15: 1 | S15: 0 | T15: 1 | U15: 1 | V15: 0 | W15: 1 | X15: =SUM(C15,F15,I15,L15,O15,R15,U15) -> 22735 | Y15: =SUM(D15,G15,J15,M15,P15,S15,V15) -> 22787 | Z15: =SUM(X15:Y15) -> 45522
A16: 3275021004 | B16: BINTARAJAYA | C16: 16210 | D16: 16268 | E16: 32385 | F16: 1133 | G16: 1215 | H16: 2335 | I16: 297 | J16: 381 | K16: 688 | L16: 20 | M16: 22 | N16: 42 | O16: 59 | P16: 58 | Q16: 116 | R16: 0 | S16: 2 | T16: 2 | U16: 0 | V16: 1 | W16: 1 | X16: =SUM(C16,F16,I16,L16,O16,R16,U16) -> 17719 | Y16: =SUM(D16,G16,J16,M16,P16,S16,V16) -> 17947 | Z16: =SUM(X16:Y16) -> 35666
A17: 3275021005 | B17: JAKASAMPURNA | C17: 33463 | D17: 33693 | E17: 67067 | F17: 3061 | G17: 3085 | H17: 6149 | I17: 871 | J17: 984 | K17: 1866 | L17: 87 | M17: 65 | N17: 147 | O17: 153 | P17: 169 | Q17: 320 | R17: 0 | S17: 1 | T17: 1 | U17: 0 | V17: 1 | W17: 1 | X17: =SUM(C17,F17,I17,L17,O17,R17,U17) -> 37635 | Y17: =SUM(D17,G17,J17,M17,P17,S17,V17) -> 37998 | Z17: =SUM(X17:Y17) -> 75633
... A74: 3275121004 | B74: JATIMURNI | C74: 11319 | D74: 11313 | E74: 22399 | F74: 1550 | G74: 1513 | H74: 3044 | I74: 1428 | J74: 1448 | K74: 2855 | L74: 29 | M74: 28 | N74: 57 | O74: 30 | P74: 27 | Q74: 58 | R74: 0 | S74: 0 | T74: 0 | U74: 0 | V74: 0 | W74: 0 | X74: =SUM(C74,F74,I74,L74,O74,R74,U74) -> 14356 | Y74: =SUM(D74,G74,J74,M74,P74,S74,V74) -> 14329 | Z74: =SUM(X74:Y74) -> 28685

Sheet JUMDUK PEND
A1: JUMLAH PENDUDUK KOTA BEKASI BERDASARKAN PENDIDIKAN SEMESTER 1 TAHUN 2026 | AF1: total Diploma
AG3: =AG8*AF3 -> 0
A4: KODE | B4: WILAYAH | C4: TIDAK/BLM SEKOLAH L | D4: TIDAK/BLM SEKOLAH P | E4: TOTAL | F4: BELUM TAMAT SD/SEDERAJAT L | G4: BELUM TAMAT SD/SEDERAJAT P | H4: TOTAL | I4: TAMAT SD/SEDERAJAT L | J4: TAMAT SD/SEDERAJAT P | K4: TOTAL | L4: SLTP/SEDERAJAT L | M4: SLTP/SEDERAJAT P | N4: TOTAL | O4: SLTA/SEDERAJAT L | P4: SLTA/SEDERAJAT P | Q4: TOTAL | R4: DIPLOMA I/II L | S4: DIPLOMA I/II P | T4: TOTAL | U4: AKADEMI/DIPL.III/S. MUDA L | V4: AKADEMI/DIPL.III/S.MUDA P | W4: TOTAL | X4: DIPLOMA IV/STRATA I L | Y4: DIPLOMA IV/STRATA I P | Z4: TOTAL | AA4: STRATA-II L | AB4: STRATA-II P | AC4: TOTAL | AD4: STRATA-III L | AE4: STRATA-III P | AF4: TOTAL | AG4: GRAND TOTAL
B6: PROSENTASE | C6: =E8/$AG$8*100 -> 19.794703 | F6: =H8/$AG$8*100 -> 9.4452465 | I6: =K8/$AG$8*100 -> 7.5807902 | L6: =N8/$AG$8*100 -> 9.8091934 | O6: =Q8/$AG$8*100 -> 37.758625 | R6: =T8/$AG$8*100 -> 0.464321 | U6: =W8/$AG$8*100 -> 3.432815 | X6: =Z8/$AG$8*100 -> 10.735304 | AA6: =AC8/$AG$8*100 -> 0.92848858 | AD6: =AF8/$AG$8*100 -> 0.050513031 | AG6: =SUM(C6:AF6) -> 100
A7: 3275 | B7: PROSENTASE | C7: =C8/E8*100 -> 51.47637 | D7: =D8/E8*100 -> 48.52363 | E7: =SUM(C7:D7) -> 100 | F7: =F8/H8*100 -> 51.203398 | G7: =G8/H8*100 -> 48.796602 | H7: =SUM(F7:G7) -> 100 | I7: =I8/K8*100 -> 42.8085 | J7: =J8/K8*100 -> 57.1915 | K7: =SUM(I7:J7) -> 100 | L7: =L8/N8*100 -> 46.479374 | M7: =M8/N8*100 -> 53.520626 | N7: =SUM(L7:M7) -> 100 | O7: =O8/Q8*100 -> 51.653849 | P7: =P8/Q8*100 -> 48.346151 | Q7: =SUM(O7:P7) -> 100 | R7: =R8/T8*100 -> 36.130844 | S7: =S8/T8*100 -> 63.869156 | T7: =SUM(R7:S7) -> 100 | U7: =U8/W8*100 -> 41.523094 | V7: =V8/W8*100 -> 58.476906 | W7: =SUM(U7:V7) -> 100 | X7: =X8/Z8*100 -> 50.09182 | Y7: =Y8/Z8*100 -> 49.90818 | Z7: =SUM(X7:Y7) -> 100 | AA7: =AA8/AC8*100 -> 59.579478 | AB7: =AB8/AC8*100 -> 40.420522 | AC7: =SUM(AA7:AB7) -> 100 | AD7: =AD8/AF8*100 -> 68.33713 | AE7: =AE8/AF8*100 -> 31.66287 | AF7: =SUM(AD7:AE7) -> 100
B8: KOTA BEKASI | C8: 265668 | D8: 250429 | E8: 516097 | F8: 126094 | G8: 120167 | H8: 246261 | I8: 84611 | J8: 113039 | K8: 197650 | L8: 118871 | M8: 136879 | N8: 255750 | O8: 508512 | P8: 475949 | Q8: 984461 | R8: 4374 | S8: 7732 | T8: 12106 | U8: 37164 | V8: 52338 | W8: 89502 | X8: 140205 | Y8: 139691 | Z8: 279896 | AA8: 14423 | AB8: 9785 | AC8: 24208 | AD8: 900 | AE8: 417 | AF8: 1317 | AG8: =E8+H8+K8+N8+Q8+T8+W8+Z8+AC8+AF8 -> 2607248
A9: 327501 | B9: BEKASI TIMUR | C9: 28733 | D9: 26878 | E9: 55611 | F9: 12821 | G9: 12144 | H9: 24965 | I9: 7525 | J9: 10491 | K9: 18016 | L9: 11595 | M9: 13995 | N9: 25590 | O9: 56316 | P9: 53717 | Q9: 110033 | R9: 558 | S9: 945 | T9: 1503 | U9: 4315 | V9: 5785 | W9: 10100 | X9: 14115 | Y9: 14206 | Z9: 28321 | AA9: 1227 | AB9: 841 | AC9: 2068 | AD9: 65 | AE9: 39 | AF9: 104
A10: 3275011001 | B10: BEKASIJAYA | C10: 6763 | D10: 6431 | E10: 13194 | F10: 3322 | G10: 3224 | H10: 6546 | I10: 2027 | J10: 2784 | K10: 4811 | L10: 3083 | M10: 3504 | N10: 6587 | O10: 12633 | P10: 12000 | Q10: 24633 | R10: 145 | S10: 246 | T10: 391 | U10: 967 | V10: 1368 | W10: 2335 | X10: 3654 | Y10: 3602 | Z10: 7256 | AA10: 349 | AB10: 254 | AC10: 603 | AD10: 20 | AE10: 7 | AF10: 27
A11: 3275011002 | B11: MARGAHAYU | C11: 6971 | D11: 6483 | E11: 13454 | F11: 3184 | G11: 2978 | H11: 6162 | I11: 2171 | J11: 2849 | K11: 5020 | L11: 3141 | M11: 3676 | N11: 6817 | O11: 13829 | P11: 12798 | Q11: 26627 | R11: 120 | S11: 198 | T11: 318 | U11: 891 | V11: 1196 | W11: 2087 | X11: 2811 | Y11: 2965 | Z11: 5776 | AA11: 284 | AB11: 183 | AC11: 467 | AD11: 18 | AE11: 13 | AF11: 31
A12: 3275011003 | B12: DURENJAYA | C12: 7863 | D12: 7410 | E12: 15273 | F12: 3350 | G12: 3151 | H12: 6501 | I12: 2029 | J12: 2922 | K12: 4951 | L12: 3133 | M12: 3833 | N12: 6966 | O12: 15785 | P12: 15109 | Q12: 30894 | R12: 146 | S12: 260 | T12: 406 | U12: 1225 | V12: 1598 | W12: 2823 | X12: 4028 | Y12: 4053 | Z12: 8081 | AA12: 348 | AB12: 250 | AC12: 598 | AD12: 15 | AE12: 10 | AF12: 25
A13: 3275011004 | B13: ARENJAYA | C13: 7136 | D13: 6554 | E13: 13690 | F13: 2965 | G13: 2791 | H13: 5756 | I13: 1298 | J13: 1936 | K13: 3234 | L13: 2238 | M13: 2982 | N13: 5220 | O13: 14069 | P13: 13810 | Q13: 27879 | R13: 147 | S13: 241 | T13: 388 | U13: 1232 | V13: 1623 | W13: 2855 | X13: 3622 | Y13: 3586 | Z13: 7208 | AA13: 246 | AB13: 154 | AC13: 400 | AD13: 12 | AE13: 9 | AF13: 21
A14: 327502 | B14: BEKASI BARAT | C14: 26151 | D14: 24211 | E14: 50362 | F14: 12600 | G14: 11813 | H14: 24413 | I14: 7988 | J14: 11102 | K14: 19090 | L14: 12148 | M14: 14264 | N14: 26412 | O14: 57151 | P14: 53781 | Q14: 110932 | R14: 412 | S14: 663 | T14: 1075 | U14: 3776 | V14: 5344 | W14: 9120 | X14: 14180 | Y14: 14203 | Z14: 28383 | AA14: 1343 | AB14: 1014 | AC14: 2357 | AD14: 80 | AE14: 32 | AF14: 112
A15: 3275021001 | B15: BINTARA | C15: 6151 | D15: 5680 | E15: 11831 | F15: 3122 | G15: 2889 | H15: 6011 | I15: 1861 | J15: 2559 | K15: 4420 | L15: 2903 | M15: 3484 | N15: 6387 | O15: 14042 | P15: 12920 | Q15: 26962 | R15: 109 | S15: 175 | T15: 284 | U15: 940 | V15: 1263 | W15: 2203 | X15: 3355 | Y15: 3445 | Z15: 6800 | AA15: 327 | AB15: 265 | AC15: 592 | AD15: 20 | AE15: 6 | AF15: 26
A16: 3275021002 | B16: KRANJI | C16: 4816 | D16: 4528 | E16: 9344 | F16: 2401 | G16: 2290 | H16: 4691 | I16: 1466 | J16: 2146 | K16: 3612 | L16: 2444 | M16: 2823 | N16: 5267 | O16: 11419 | P16: 10547 | Q16: 21966 | R16: 72 | S16: 108 | T16: 180 | U16: 548 | V16: 740 | W16: 1288 | X16: 1616 | Y16: 1712 | Z16: 3328 | AA16: 122 | AB16: 113 | AC16: 235 | AD16: 6 | AE16: 2 | AF16: 8
A17: 3275021003 | B17: KOTABARU | C17: 4564 | D17: 4225 | E17: 8789 | F17: 1981 | G17: 1720 | H17: 3701 | I17: 1135 | J17: 1577 | K17: 2712 | L17: 1772 | M17: 2116 | N17: 3888 | O17: 9562 | P17: 9253 | Q17: 18815 | R17: 80 | S17: 119 | T17: 199 | U17: 741 | V17: 979 | W17: 1720 | X17: 2698 | Y17: 2649 | Z17: 5347 | AA17: 194 | AB17: 143 | AC17: 337 | AD17: 8 | AE17: 6 | AF17: 14
A18: 3275021004 | B18: BINTARAJAYA | C18: 3537 | D18: 3211 | E18: 6748 | F18: 1520 | G18: 1484 | H18: 3004 | I18: 1136 | J18: 1519 | K18: 2655 | L18: 1588 | M18: 1900 | N18: 3488 | O18: 6932 | P18: 6670 | Q18: 13602 | R18: 59 | S18: 98 | T18: 157 | U18: 543 | V18: 793 | W18: 1336 | X18: 2175 | Y18: 2135 | Z18: 4310 | AA18: 218 | AB18: 132 | AC18: 350 | AD18: 11 | AE18: 5 | AF18: 16
A19: 3275021005 | B19: JAKASAMPURNA | C19: 7083 | D19: 6567 | E19: 13650 | F19: 3576 | G19: 3430 | H19: 7006 | I19: 2390 | J19: 3301 | K19: 5691 | L19: 3441 | M19: 3941 | N19: 7382 | O19: 15196 | P19: 14391 | Q19: 29587 | R19: 92 | S19: 163 | T19: 255 | U19: 1004 | V19: 1569 | W19: 2573 | X19: 4336 | Y19: 4262 | Z19: 8598 | AA19: 482 | AB19: 361 | AC19: 843 | AD19: 35 | AE19: 13 | AF19: 48
A20: 327503 | B20: BEKASI UTARA | C20: 33306 | D20: 30943 | E20: 64249 | F20: 15983 | G20: 15323 | H20: 31306 | I20: 12023 | J20: 15545 | K20: 27568 | L20: 15626 | M20: 18941 | N20: 34567 | O20: 71877 | P20: 65620 | Q20: 137497 | R20: 627 | S20: 1228 | T20: 1855 | U20: 5464 | V20: 7398 | W20: 12862 | X20: 18006 | Y20: 18070 | Z20: 36076 | AA20: 1521 | AB20: 1014 | AC20: 2535 | AD20: 80 | AE20: 27 | AF20: 107
... A76: 3275121004 | B76: JATIMURNI | C76: 2710 | D76: 2631 | E76: 5341 | F76: 1427 | G76: 1305 | H76: 2732 | I76: 1050 | J76: 1543 | K76: 2593 | L76: 1472 | M76: 1695 | N76: 3167 | O76: 5778 | P76: 5055 | Q76: 10833 | R76: 44 | S76: 66 | T76: 110 | U76: 386 | V76: 529 | W76: 915 | X76: 1342 | Y76: 1413 | Z76: 2755 | AA76: 134 | AB76: 88 | AC76: 222 | AD76: 13 | AE76: 4 | AF76: 17

Sheet JUMDUK PEKERJAAN
A1: JUMLAH PENDUDUK BERDASARKAN PEKERJAAN SESUAI DKB SEMESTER 1 TAHUN 2026
A3: IDEM | B3: KODE | C3: WILAYAH | D3: BELUM/TIDAK BEKERJA L | E3: BELUM/TIDAK BEKERJA P | F3: TOTAL | G3: MENGURUS RUMAH TANGGA L | H3: MENGURUS RUMAH TANGGA P | I3: TOTAL | J3: PELAJAR/MAHASISWA L | K3: PELAJAR/MAHASISWA P | L3: TOTAL | M3: PENSIUNAN L | N3: PENSIUNAN P | O3: TOTAL | P3: APARATUR SIPIL NEGARA (ASN) L | Q3: APARATUR SIPIL NEGARA (ASN) P | R3: TOTAL | S3: TENTARA NASIONAL INDONESIA (TNI) L | T3: TENTARA NASIONAL INDONESIA (TNI) P | U3: TOTAL | V3: KEPOLISIAN RI (POLRI) L | W3: KEPOLISIAN RI (POLRI) P | X3: TOTAL | Y3: PERDAGANGAN L | Z3: PERDAGANGAN P | AA3: TOTAL | AB3: PETANI/PEKEBUN L | AC3: PETANI/PEKEBUN P | AD3: TOTAL | AE3: PETERNAK L | AF3: PETERNAK P | AG3: TOTAL | AH3: NELAYAN/PERIKANAN L | AI3: NELAYAN/PERIKANAN P | AJ3: TOTAL | AK3: INDUSTRI L | AL3: INDUSTRI P | AM3: TOTAL | AN3: KONSTRUKSI L | AO3: KONSTRUKSI P | AP3: TOTAL | AQ3: TRANSPORTASI L | AR3: TRANSPORTASI P | AS3: TOTAL | AT3: KARYAWAN SWASTA L | AU3: KARYAWAN SWASTA P | AV3: TOTAL | AW3: KARYAWAN BUMN L | AX3: KARYAWAN BUMN P | AY3: TOTAL | AZ3: KARYAWAN BUMD L | BA3: KARYAWAN BUMD P | BB3: TOTAL | BC3: KARYAWAN HONORER L | BD3: KARYAWAN HONORER P | BE3: TOTAL | BF3: BURUH HARIAN LEPAS L | BG3: BURUH HARIAN LEPAS P | BH3: TOTAL | BI3: BURUH TANI/PERKEBUNAN L | BJ3: BURUH TANI/PERKEBUNAN P | BK3: TOTAL | BL3: BURUH NELAYAN/PERIKANAN L | BM3: BURUH NELAYAN/PERIKANAN P | BN3: TOTAL | BO3: BURUH PETERNAKAN L | BP3: BURUH PETERNAKAN P | BQ3: TOTAL | BR3: PEMBANTU RUMAH TANGGA L | BS3: PEMBANTU RUMAH TANGGA P | BT3: TOTAL | BU3: TUKANG CUKUR L | BV3: TUKANG CUKUR P | BW3: TOTAL | BX3: TUKANG LISTRIK L | BY3: TUKANG LISTRIK P | BZ3: TOTAL | CA3: TUKANG BATU L | CB3: TUKANG BATU P | CC3: TOTAL | CD3: TUKANG KAYU L | CE3: TUKANG KAYU P | CF3: TOTAL | CG3: TUKANG SOL SEPATU L | CH3: TUKANG SOL SEPATU P | CI3: TOTAL | CJ3: TUKANG LAS/PANDAI BESI L | CK3: TUKANG LAS/PANDAI BESI P | CL3: TOTAL | CM3: TUKANG JAHIT L | CN3: TUKANG JAHIT P | CO3: TOTAL | CP3: TUKANG GIGI L | CQ3: TUKANG GIGI P | CR3: TOTAL | CS3: PENATA RIAS L | CT3: PENATA RIAS P | CU3: TOTAL | CV3: PENATA BUSANA L | CW3: PENATA BUSANA P | CX3: TOTAL | CY3: PENATA RAMBUT L | CZ3: PENATA RAMBUT P | DA3: TOTAL | DB3: MEKANIK L | DC3: MEKANIK P | DD3: TOTAL | DE3: SENIMAN L | DF3: SENIMAN P | DG3: TOTAL | DH3: TABIB L | DI3: TABIB P | DJ3: TOTAL | DK3: PARAJI L | DL3: PARAJI P | DM3: TOTAL | DN3: PERANCANG BUSANA L | DO3: PERANCANG BUSANA P | DP3: TOTAL | DQ3: PENTERJEMAH L | DR3: PENTERJEMAH P | DS3: TOTAL | DT3: IMAM MASJID L | DU3: IMAM MASJID P | DV3: TOTAL | DW3: PENDETA L | DX3: PENDETA P | DY3: TOTAL | DZ3: PASTOR L | EA3: PASTOR P | EB3: TOTAL | EC3: WARTAWAN L | ED3: WARTAWAN P | EE3: TOTAL | EF3: USTADZ/MUBALIGH L | EG3: USTADZ/MUBALIGH P | EH3: TOTAL | EI3: JURU MASAK L | EJ3: JURU MASAK P | EK3: TOTAL | EL3: PROMOTOR ACARA L | EM3: PROMOTOR ACARA P | EN3: TOTAL | EO3: ANGGOTA DPR RI L | EP3: ANGGOTA DPR RI P | EQ3: TOTAL | ER3: ANGGOTA DPD RI L | ES3: ANGGOTA DPD RI P | ET3: TOTAL | EU3: ANGGOTA BPK L | EV3: ANGGOTA BPK P | EW3: TOTAL | EX3: PRESIDEN L | EY3: PRESIDEN P | EZ3: TOTAL | FA3: WAKIL PRESIDEN L | FB3: WAKIL PRESIDEN P | FC3: TOTAL | FD3: ANGGOTA MAHKAMAH KONSTITUSI L | FE3: ANGGOTA MAHKAMAH KONSTITUSI P | FF3: TOTAL | FG3: ANGGOTA KABINET KEMENTRIAN L | FH3: ANGGOTA KABINET KEMENTRIAN P | FI3: TOTAL | FJ3: DUTA BESAR L | FK3: DUTA BESAR P | FL3: TOTAL | FM3: GUBERNUR L | FN3: GUBERNUR P | FO3: TOTAL | FP3: WAKIL GUBERNUR L | FQ3: WAKIL GUBERNUR P | FR3: TOTAL | FS3: BUPATI L | FT3: BUPATI P | FU3: TOTAL | FV3: WAKIL BUPATI L | FW3: WAKIL BUPATI P | FX3: TOTAL | FY3: WALIKOTA L | FZ3: WALIKOTA P | GA3: TOTAL | GB3: WAKIL WALIKOTA L | GC3: WAKIL WALIKOTA P | GD3: TOTAL | GE3: ANGGOTA DPRD PROP. L | GF3: ANGGOTA DPRD PROP. P | GG3: TOTAL | GH3: ANGGOTA DPRD KAB./KOTA L | GI3: ANGGOTA DPRD KAB./KOTA P | GJ3: TOTAL | GK3: DOSEN L | GL3: DOSEN P | GM3: TOTAL | GN3: GURU L | GO3: GURU P | GP3: TOTAL | GQ3: PILOT L | GR3: PILOT P | GS3: TOTAL | GT3: PENGACARA L | GU3: PENGACARA P | GV3: TOTAL | GW3: NOTARIS L | GX3: NOTARIS P | GY3: TOTAL | GZ3: ARSITEK L | HA3: ARSITEK P | HB3: TOTAL | HC3: AKUNTAN L | HD3: AKUNTAN P | HE3: TOTAL | HF3: KONSULTAN L | HG3: KONSULTAN P | HH3: TOTAL | HI3: DOKTER L | HJ3: DOKTER P | HK3: TOTAL | HL3: BIDAN L | HM3: BIDAN P | HN3: TOTAL | HO3: PERAWAT L | HP3: PERAWAT P | HQ3: TOTAL | HR3: APOTEKER L | HS3: APOTEKER P | HT3: TOTAL | HU3: PSIKIATER/PSIKOLOG L | HV3: PSIKIATER/PSIKOLOG P | HW3: TOTAL | HX3: PENYIAR TELEVISI L | HY3: PENYIAR TELEVISI P | HZ3: TOTAL | IA3: PENYIAR RADIO L | IB3: PENYIAR RADIO P | IC3: TOTAL | ID3: PELAUT L | IE3: PELAUT P | IF3: TOTAL | IG3: PENELITI L | IH3: PENELITI P | II3: TOTAL | IJ3: SOPIR L | IK3: SOPIR P | IL3: TOTAL | IM3: PIALANG L | IN3: PIALANG P | IO3: TOTAL | IP3: PARANORMAL L | IQ3: PARANORMAL P | IR3: TOTAL | IS3: PEDAGANG L | IT3: PEDAGANG P | IU3: TOTAL | IV3: PERANGKAT DESA L | IW3: PERANGKAT DESA P | IX3: TOTAL | IY3: KEPALA DESA L | IZ3: KEPALA DESA P | JA3: TOTAL | JB3: BIARAWAN/BIARAWATI L | JC3: BIARAWAN/BIARAWATI P | JD3: TOTAL | JE3: WIRASWASTA L | JF3: WIRASWASTA P | JG3: TOTAL | JH3: ANGGOTA LEMBAGA TINGGI LAINNYA L | JI3: ANGGOTA LEMBAGA TINGGI LAINNYA P | JJ3: TOTAL | JK3: ARTIS L | JL3: ARTIS P | JM3: TOTAL | JN3: ATLIT L | JO3: ATLIT P | JP3: TOTAL | JQ3: CHEFF L | JR3: CHEFF P | JS3: TOTAL | JT3: MANAJER L | JU3: MANAJER P | JV3: TOTAL | JW3: TENAGA TATA USAHA L | JX3: TENAGA TATA USAHA P | JY3: TOTAL | JZ3: OPERATOR L | KA3: OPERATOR P | KB3: TOTAL | KC3: PEKERJA PENGOLAHAN KERAJINAN L | KD3: PEKERJA PENGOLAHAN KERAJINAN P | KE3: TOTAL | KF3: TEKNISI L | KG3: TEKNISI P | KH3: TOTAL | KI3: ASISTEN AHLI L | KJ3: ASISTEN AHLI P | KK3: TOTAL | KL3: GEMBALA L | KM3: GEMBALA P | KN3: TOTAL | KO3: BIARAWAN L | KP3: BIARAWAN P | KQ3: TOTAL | KR3: PANDITA L | KS3: PANDITA P | KT3: TOTAL | KU3: PINANDITA L | KV3: PINANDITA P | KW3: TOTAL | KX3: BHIKKHU L | KY3: BHIKKHU P | KZ3: TOTAL | LA3: XUESHI L | LB3: XUESHI P | LC3: TOTAL | LD3: WENSI L | LE3: WENSI P | LF3: TOTAL | LG3: JIAOSHENG L | LH3: JIAOSHENG P | LI3: TOTAL | LJ3: LAINNYA L | LK3: LAINNYA P | LL3: TOTAL
A4: 2 | B4: 3275 | C4: KOTA BEKASI | D4: 279231 | E4: 253945 | F4: =D4+E4 -> 533176 | G4: 238 | H4: 462978 | I4: =G4+H4 -> 463216 | J4: 328986 | K4: 284108 | L4: =J4+K4 -> 613094 | M4: 15845 | N4: 6415 | O4: =M4+N4 -> 22260 | P4: 21556 | Q4: 18575 | R4: =P4+Q4 -> 40131 | S4: 6700 | T4: 515 | U4: =S4+T4 -> 7215 | V4: 3858 | W4: 370 | X4: =V4+W4 -> 4228 | Y4: 7021 | Z4: 1807 | AA4: =Y4+Z4 -> 8828 | AB4: 2329 | AC4: 546 | AD4: =AB4+AC4 -> 2875 | AE4: 104 | AF4: 11 | AG4: =AE4+AF4 -> 115 | AH4: 66 | AI4: 0 | AJ4: =AH4+AI4 -> 66 | AK4: 2201 | AL4: 377 | AM4: =AK4+AL4 -> 2578 | AN4: 673 | AO4: 22 | AP4: =AN4+AO4 -> 695 | AQ4: 1534 | AR4: 23 | AS4: =AQ4+AR4 -> 1557 | AT4: 404669 | AU4: 203320 | AV4: =AT4+AU4 -> 607989 | AW4: 8982 | AX4: 4629 | AY4: =AW4+AX4 -> 13611 | AZ4: 594 | BA4: 383 | BB4: =AZ4+BA4 -> 977 | BC4: 2596 | BD4: 1634 | BE4: =BC4+BD4 -> 4230 | BF4: 36078 | BG4: 1706 | BH4: =BF4+BG4 -> 37784 | BI4: 1300 | BJ4: 144 | BK4: =BI4+BJ4 -> 1444 | BL4: 27 | BM4: 1 | BN4: =BL4+BM4 -> 28 | BO4: 37 | BP4: 5 | BQ4: =BO4+BP4 -> 42 | BR4: 19 | BS4: 613 | BT4: =BR4+BS4 -> 632 | BU4: 22 | BV4: 0 | BW4: =BU4+BV4 -> 22 | BX4: 80 | BY4: 2 | BZ4: =BX4+BY4 -> 82 | CA4: 321 | CB4: 0 | CC4: =CA4+CB4 -> 321 | CD4: 119 | CE4: 0 | CF4: =CD4+CE4 -> 119 | CG4: 9 | CH4: 0 | CI4: =CG4+CH4 -> 9 | CJ4: 92 | CK4: 1 | CL4: =CJ4+CK4 -> 93 | CM4: 192 | CN4: 152 | CO4: =CM4+CN4 -> 344 | CP4: 8 | CQ4: 2 | CR4: =CP4+CQ4 -> 10 | CS4: 7 | CT4: 77 | CU4: =CS4+CT4 -> 84 | CV4: 3 | CW4: 11 | CX4: =CV4+CW4 -> 14 | CY4: 14 | CZ4: 63 | DA4: =CY4+CZ4 -> 77 | DB4: 540 | DC4: 1 | DD4: =DB4+DC4 -> 541 | DE4: 508 | DF4: 107 | DG4: =DE4+DF4 -> 615 | DH4: 16 | DI4: 2 | DJ4: =DH4+DI4 -> 18 | DK4: 4 | DL4: 12 | DM4: =DK4+DL4 -> 16 | DN4: 3 | DO4: 11 | DP4: =DN4+DO4 -> 14 | DQ4: 7 | DR4: 11 | DS4: =DQ4+DR4 -> 18 | DT4: 27 | DU4: 0 | DV4: =DT4+DU4 -> 27 | DW4: 475 | DX4: 169 | DY4: =DW4+DX4 -> 644 | DZ4: 23 | EA4: 1 | EB4: =DZ4+EA4 -> 24 | EC4: 869 | ED4: 153 | EE4: =EC4+ED4 -> 1022 | EF4: 192 | EG4: 42 | EH4: =EF4+EG4 -> 234 | EI4: 30 | EJ4: 27 | EK4: =EI4+EJ4 -> 57 | EL4: 4 | EM4: 0 | EN4: =EL4+EM4 -> 4 | EO4: 11 | EP4: 2 | EQ4: =EO4+EP4 -> 13 | ER4: 3 | ES4: 0 | ET4: =ER4+ES4 -> 3 | EU4: 1 | EV4: 2 | EW4: =EU4+EV4 -> 3 | EX4: 0 | EY4: 0 | EZ4: =EX4+EY4 -> 0 | FA4: 0 | FB4: 0 | FC4: =FA4+FB4 -> 0 | FD4: 5 | FE4: 0 | FF4: =FD4+FE4 -> 5 | FG4: 0 | FH4: 0 | FI4: =FG4+FH4 -> 0 | FJ4: 0 | FK4: 0 | FL4: =FJ4+FK4 -> 0 | FM4: 0 | FN4: 0 | FO4: =FM4+FN4 -> 0 | FP4: 1 | FQ4: 0 | FR4: =FP4+FQ4 -> 1 | FS4: 0 | FT4: 0 | FU4: =FS4+FT4 -> 0 | FV4: 0 | FW4: 0 | FX4: =FV4+FW4 -> 0 | FY4: 1 | FZ4: 0 | GA4: =FY4+FZ4 -> 1 | GB4: 1 | GC4: 0 | GD4: =GB4+GC4 -> 1 | GE4: 1 | GF4: 1 | GG4: =GE4+GF4 -> 2 | GH4: 29 | GI4: 4 | GJ4: =GH4+GI4 -> 33 | GK4: 1232 | GL4: 1131 | GM4: =GK4+GL4 -> 2363 | GN4: 6966 | GO4: 18350 | GP4: =GN4+GO4 -> 25316 | GQ4: 269 | GR4: 9 | GS4: =GQ4+GR4 -> 278 | GT4: 600 | GU4: 108 | GV4: =GT4+GU4 -> 708 | GW4: 65 | GX4: 108 | GY4: =GW4+GX4 -> 173 | GZ4: 134 | HA4: 48 | HB4: =GZ4+HA4 -> 182 | HC4: 54 | HD4: 39 | HE4: =HC4+HD4 -> 93 | HF4: 254 | HG4: 65 | HH4: =HF4+HG4 -> 319 | HI4: 1416 | HJ4: 3315 | HK4: =HI4+HJ4 -> 4731 | HL4: 0 | HM4: 1849 | HN4: =HL4+HM4 -> 1849 | HO4: 401 | HP4: 3056 | HQ4: =HO4+HP4 -> 3457 | HR4: 62 | HS4: 364 | HT4: =HR4+HS4 -> 426 | HU4: 8 | HV4: 76 | HW4: =HU4+HV4 -> 84 | HX4: 3 | HY4: 4 | HZ4: =HX4+HY4 -> 7 | IA4: 3 | IB4: 6 | IC4: =IA4+IB4 -> 9 | ID4: 1011 | IE4: 7 | IF4: =ID4+IE4 -> 1018 | IG4: 39 | IH4: 18 | II4: =IG4+IH4 -> 57 | IJ4: 3912 | IK4: 3 | IL4: =IJ4+IK4 -> 3915 | IM4: 11 | IN4: 4 | IO4: =IM4+IN4 -> 15 | IP4: 6 | IQ4: 2 | IR4: =IP4+IQ4 -> 8 | IS4: 7835 | IT4: 2288 | IU4: =IS4+IT4 -> 10123 | IV4: 41 | IW4: 9 | IX4: =IV4+IW4 -> 50 | IY4: 3 | IZ4: 0 | JA4: =IY4+IZ4 -> 3 | JB4: 3 | JC4: 45 | JD4: =JB4+JC4 -> 48 | JE4: 148155 | JF4: 32496 | JG4: =JE4+JF4 -> 180651 | JH4: 45 | JI4: 34 | JJ4: =JH4+JI4 -> 79 | JK4: 3 | JL4: 1 | JM4: =JK4+JL4 -> 4 | JN4: 9 | JO4: 3 | JP4: =JN4+JO4 -> 12 | JQ4: 2 | JR4: 0 | JS4: =JQ4+JR4 -> 2 | JT4: 1 | JU4: 1 | JV4: =JT4+JU4 -> 2 | JW4: 2 | JX4: 1 | JY4: =JW4+JX4 -> 3 | JZ4: 0 | KA4: 0 | KB4: =JZ4+KA4 -> 0 | KC4: 0 | KD4: 0 | KE4: =KC4+KD4 -> 0 | KF4: 4 | KG4: 1 | KH4: =KF4+KG4 -> 5 | KI4: 0 | KJ4: 0 | KK4: =KI4+KJ4 -> 0 | KL4: 0 | KM4: 0 | KN4: =KL4+KM4 -> 0 | KO4: 0 | KP4: 0 | KQ4: =KO4+KP4 -> 0 | KR4: 0 | KS4: 0 | KT4: =KR4+KS4 -> 0 | KU4: 0 | KV4: 0 | KW4: =KU4+KV4 -> 0 | KX4: 0 | KY4: 0 | KZ4: =KX4+KY4 -> 0 | LA4: 0 | LB4: 0 | LC4: =LA4+LB4 -> 0 | LD4: 0 | LE4: 0 | LF4: =LD4+LE4 -> 0 | LG4: 0 | LH4: 0 | LI4: =LG4+LH4 -> 0 | LJ4: 11 | LK4: 5 | LL4: =LJ4+LK4 -> 16 | LM4: =F4+I4+L4+O4+R4+U4+X4+AA4+AD4+AG4+AJ4+AM4+AP4+AS4+AV4+AY4+BB4+BE4+BH4+BK4+BN4+BQ4+BT4+BW4+BZ4+CC4+CF4+CI4+CL4+CO4+CR4+CU4+CX4+DA4+DD4+DG4+DJ4+DM4+DP4+DS4+DV4+DY4+EB4+EE4+EH4+EK4+EN4+EQ4+ET4+EW4+EZ4+FC4+FF4+FI4+FL4+FO4+FR4+FU4+FX4+GA4+GD4+GG4+GJ4+GM4+GP4+GS4+GV4+GY4+HB4+HE4+HH4+HK4+HN4+HQ4+HT4+HW4+HZ4+IC4+IF4+II4+IL4+IO4+IR4+IU4+IX4+JA4+JD4+JG4+JJ4+JM4+JP4+JS4+JV4+JY4+KB4+KE4+KH4+KK4+LL4 -> 2607248
A5: 3 | B5: 327501 | C5: BEKASI TIMUR | D5: 30755 | E5: 27690 | F5: =D5+E5 -> 58445 | G5: 28 | H5: 47912 | I5: =G5+H5 -> 47940 | J5: 33341 | K5: 28889 | L5: =J5+K5 -> 62230 | M5: 2178 | N5: 805 | O5: =M5+N5 -> 2983 | P5: 2544 | Q5: 2271 | R5: =P5+Q5 -> 4815 | S5: 225 | T5: 18 | U5: =S5+T5 -> 243 | V5: 308 | W5: 20 | X5: =V5+W5 -> 328 | Y5: 522 | Z5: 167 | AA5: =Y5+Z5 -> 689 | AB5: 121 | AC5: 50 | AD5: =AB5+AC5 -> 171 | AE5: 5 | AF5: 0 | AG5: =AE5+AF5 -> 5 | AH5: 4 | AI5: 0 | AJ5: =AH5+AI5 -> 4 | AK5: 28 | AL5: 8 | AM5: =AK5+AL5 -> 36 | AN5: 33 | AO5: 2 | AP5: =AN5+AO5 -> 35 | AQ5: 91 | AR5: 3 | AS5: =AQ5+AR5 -> 94 | AT5: 41114 | AU5: 22782 | AV5: =AT5+AU5 -> 63896 | AW5: 1010 | AX5: 486 | AY5: =AW5+AX5 -> 1496 | AZ5: 88 | BA5: 61 | BB5: =AZ5+BA5 -> 149 | BC5: 401 | BD5: 262 | BE5: =BC5+BD5 -> 663 | BF5: 3659 | BG5: 209 | BH5: =BF5+BG5 -> 3868 | BI5: 63 | BJ5: 12 | BK5: =BI5+BJ5 -> 75 | BL5: 0 | BM5: 0 | BN5: =BL5+BM5 -> 0 | BO5: 1 | BP5: 1 | BQ5: =BO5+BP5 -> 2 | BR5: 1 | BS5: 81 | BT5: =BR5+BS5 -> 82 | BU5: 5 | BV5: 0 | BW5: =BU5+BV5 -> 5 | BX5: 9 | BY5: 2 | BZ5: =BX5+BY5 -> 11 | CA5: 45 | CB5: 0 | CC5: =CA5+CB5 -> 45 | CD5: 9 | CE5: 0 | CF5: =CD5+CE5 -> 9 | CG5: 0 | CH5: 0 | CI5: =CG5+CH5 -> 0 | CJ5: 17 | CK5: 0 | CL5: =CJ5+CK5 -> 17 | CM5: 27 | CN5: 28 | CO5: =CM5+CN5 -> 55 | CP5: 1 | CQ5: 1 | CR5: =CP5+CQ5 -> 2 | CS5: 1 | CT5: 21 | CU5: =CS5+CT5 -> 22 | CV5: 0 | CW5: 1 | CX5: =CV5+CW5 -> 1 | CY5: 4 | CZ5: 8 | DA5: =CY5+CZ5 -> 12 | DB5: 81 | DC5: 0 | DD5: =DB5+DC5 -> 81 | DE5: 56 | DF5: 9 | DG5: =DE5+DF5 -> 65 | DH5: 5 | DI5: 1 | DJ5: =DH5+DI5 -> 6 | DK5: 0 | DL5: 4 | DM5: =DK5+DL5 -> 4 | DN5: 0 | DO5: 3 | DP5: =DN5+DO5 -> 3 | DQ5: 2 | DR5: 2 | DS5: =DQ5+DR5 -> 4 | DT5: 6 | DU5: 0 | DV5: =DT5+DU5 -> 6 | DW5: 59 | DX5: 28 | DY5: =DW5+DX5 -> 87 | DZ5: 4 | EA5: 0 | EB5: =DZ5+EA5 -> 4 | EC5: 84 | ED5: 18 | EE5: =EC5+ED5 -> 102 | EF5: 24 | EG5: 6 | EH5: =EF5+EG5 -> 30 | EI5: 4 | EJ5: 7 | EK5: =EI5+EJ5 -> 11 | EL5: 0 | EM5: 0 | EN5: =EL5+EM5 -> 0 | EO5: 0 | EP5: 0 | EQ5: =EO5+EP5 -> 0 | ER5: 0 | ES5: 0 | ET5: =ER5+ES5 -> 0 | EU5: 0 | EV5: 0 | EW5: =EU5+EV5 -> 0 | EX5: 0 | EY5: 0 | EZ5: =EX5+EY5 -> 0 | FA5: 0 | FB5: 0 | FC5: =FA5+FB5 -> 0 | FD5: 0 | FE5: 0 | FF5: =FD5+FE5 -> 0 | FG5: 0 | FH5: 0 | FI5: =FG5+FH5 -> 0 | FJ5: 0 | FK5: 0 | FL5: =FJ5+FK5 -> 0 | FM5: 0 | FN5: 0 | FO5: =FM5+FN5 -> 0 | FP5: 0 | FQ5: 0 | FR5: =FP5+FQ5 -> 0 | FS5: 0 | FT5: 0 | FU5: =FS5+FT5 -> 0 | FV5: 0 | FW5: 0 | FX5: =FV5+FW5 -> 0 | FY5: 1 | FZ5: 0 | GA5: =FY5+FZ5 -> 1 | GB5: 0 | GC5: 0 | GD5: =GB5+GC5 -> 0 | GE5: 0 | GF5: 0 | GG5: =GE5+GF5 -> 0 | GH5: 2 | GI5: 0 | GJ5: =GH5+GI5 -> 2 | GK5: 134 | GL5: 128 | GM5: =GK5+GL5 -> 262 | GN5: 706 | GO5: 1961 | GP5: =GN5+GO5 -> 2667 | GQ5: 6 | GR5: 0 | GS5: =GQ5+GR5 -> 6 | GT5: 50 | GU5: 13 | GV5: =GT5+GU5 -> 63 | GW5: 7 | GX5: 6 | GY5: =GW5+GX5 -> 13 | GZ5: 12 | HA5: 4 | HB5: =GZ5+HA5 -> 16 | HC5: 7 | HD5: 3 | HE5: =HC5+HD5 -> 10 | HF5: 25 | HG5: 9 | HH5: =HF5+HG5 -> 34 | HI5: 147 | HJ5: 294 | HK5: =HI5+HJ5 -> 441 | HL5: 0 | HM5: 206 | HN5: =HL5+HM5 -> 206 | HO5: 32 | HP5: 373 | HQ5: =HO5+HP5 -> 405 | HR5: 10 | HS5: 48 | HT5: =HR5+HS5 -> 58 | HU5: 2 | HV5: 3 | HW5: =HU5+HV5 -> 5 | HX5: 0 | HY5: 0 | HZ5: =HX5+HY5 -> 0 | IA5: 1 | IB5: 1 | IC5: =IA5+IB5 -> 2 | ID5: 123 | IE5: 0 | IF5: =ID5+IE5 -> 123 | IG5: 1 | IH5: 4 | II5: =IG5+IH5 -> 5 | IJ5: 442 | IK5: 0 | IL5: =IJ5+IK5 -> 442 | IM5: 4 | IN5: 2 | IO5: =IM5+IN5 -> 6 | IP5: 0 | IQ5: 0 | IR5: =IP5+IQ5 -> 0 | IS5: 1170 | IT5: 376 | IU5: =IS5+IT5 -> 1546 | IV5: 4 | IW5: 3 | IX5: =IV5+IW5 -> 7 | IY5: 0 | IZ5: 0 | JA5: =IY5+IZ5 -> 0 | JB5: 1 | JC5: 0 | JD5: =JB5+JC5 -> 1 | JE5: 17413 | JF5: 3736 | JG5: =JE5+JF5 -> 21149 | JH5: 5 | JI5: 0 | JJ5: =JH5+JI5 -> 5 | JK5: 0 | JL5: 0 | JM5: =JK5+JL5 -> 0 | JN5: 1 | JO5: 1 | JP5: =JN5+JO5 -> 2 | JQ5: 0 | JR5: 0 | JS5: =JQ5+JR5 -> 0 | JT5: 0 | JU5: 0 | JV5: =JT5+JU5 -> 0 | JW5: 0 | JX5: 1 | JY5: =JW5+JX5 -> 1 | JZ5: 0 | KA5: 0 | KB5: =JZ5+KA5 -> 0 | KC5: 0 | KD5: 0 | KE5: =KC5+KD5 -> 0 | KF5: 0 | KG5: 0 | KH5: =KF5+KG5 -> 0 | KI5: 0 | KJ5: 0 | KK5: =KI5+KJ5 -> 0 | KL5: 0 | KM5: 0 | KN5: =KL5+KM5 -> 0 | KO5: 0 | KP5: 0 | KQ5: =KO5+KP5 -> 0 | KR5: 0 | KS5: 0 | KT5: =KR5+KS5 -> 0 | KU5: 0 | KV5: 0 | KW5: =KU5+KV5 -> 0 | KX5: 0 | KY5: 0 | KZ5: =KX5+KY5 -> 0 | LA5: 0 | LB5: 0 | LC5: =LA5+LB5 -> 0 | LD5: 0 | LE5: 0 | LF5: =LD5+LE5 -> 0 | LG5: 0 | LH5: 0 | LI5: =LG5+LH5 -> 0 | LJ5: 1 | LK5: 1 | LL5: =LJ5+LK5 -> 2
